<?xml version="1.0"?>
<robot name="scara">
	
	<gazebo>
		<plugin name="gazebo_ros_control" filename="libgazebo_ros_control.so">
			<robotNamespace>/robot</robotNamespace>
		</plugin>
	</gazebo>

<!-- Links -->

	<link name="base_link">
		<inertial>
			<origin xyz="0 0 0.65" /> 
			<mass value="110.27" />
			<inertia  ixx="0" ixy="0.0"  ixz="0.0"  iyy="0"  iyz="0.0"  izz="0" />
		</inertial>
		<visual>
			<origin xyz="0 0 0.65" rpy="0 0 0" />
			<geometry>
				<cylinder length="1.3" radius="0.1"/>
			</geometry>
			<material name="matbase"/>
		</visual>
		<collision>
			<origin xyz="0 0 0.65" rpy="0 0 0" />
			<geometry>
				<cylinder length="1.3" radius="0.1"/>
			</geometry>
			<material name="mat1"/>
		</collision>
	</link>

	<link name="motor1">
		<inertial>
			<origin xyz="0 0 0" /> 
			<mass value="5.4290" />
			<inertia  ixx="0.01320977" ixy="0.0"  ixz="0.0"  iyy="0.01320977"  iyz="0.0"  izz="0.01737175" />
		</inertial>
		<visual>
			<geometry>
				<cylinder length="0.1" radius="0.08"/>
			</geometry>
			<material name="mat1"/>
		</visual>
		<collision>
			<origin xyz="0 0 0" rpy="0 0 0" />
			<geometry>
				<cylinder length="0.1" radius="0.08"/>
			</geometry>
			<material name="mat1"/>
		</collision>
	</link>

	<link name="arm1">
		<inertial>
			<origin xyz=".4 0 0.0" rpy="0 1.5707963267948 0" /> 
			<mass value="10.857" />
			<inertia  ixx="0.57905836" ixy="0.0"  ixz="0.0"  iyy="0"  iyz="0.0"  izz="0.57905836" />
		</inertial>
		<visual>
			<origin xyz=".4 0 0.0" rpy="0 1.5707963267948 0" />
			<geometry>
				<cylinder length="0.8" radius="0.04"/>
			</geometry>
			<material name="mat1"/>
		</visual>
		<collision>
			<origin xyz=".4 0 0.0" rpy="0 1.5707963267948 0" />
			<geometry>
				<cylinder length="0.8" radius="0.04"/>
			</geometry>
			<material name="mat1"/>
		</collision>
	</link>

	<link name="endarm1">
		<inertial>
			<origin xyz=".8 0 0.0" rpy="0 0 0" /> 
			<mass value="4.156" />
			<inertia  ixx="0.0085511" ixy="0.0"  ixz="0.0"  iyy="0.0085511"  iyz="0.0"  izz="0.010183" />
		</inertial>
		<visual>
			<origin xyz=".8 0 0.0" rpy="0 0 0" />
			<geometry>
				<cylinder length="0.1" radius="0.07"/>
			</geometry>
			<material name="mat1"/>
		</visual>
		<collision>
			<origin xyz=".8 0 0.0" rpy="0 0 0" />
			<geometry>
				<cylinder length="0.1" radius="0.07"/>
			</geometry>
			<material name="mat1"/>
		</collision>
	</link>

	<link name="motor2">
		<inertial>
			<origin xyz="0 0 0" /> 
			<mass value="2.443" />
			<inertia  ixx="0.0035149" ixy="0.0"  ixz="0.0"  iyy="0.0035149"  iyz="0.0"  izz="0.00439722" />
		</inertial>
		<visual>
			<geometry>
				<cylinder length="0.08" radius="0.06"/>
			</geometry>
			<material name="mat2"/>
		</visual>
		<collision>
			<origin xyz="0 0 0.0" rpy="0 0 0" />
			<geometry>
				<cylinder length="0.08" radius="0.06"/>
			</geometry>
			<material name="mat1"/>
		</collision>
	</link>

	<link name="arm2">
		<inertial>
			<origin xyz="0 -.2 0.0" rpy="1.5707963267948 0 0" /> 
			<mass value="3.054" />
				<inertia  ixx="0.04071504" ixy="0.0"  ixz="0.0"  iyy="0"  iyz="0.0"  izz="0.04071504" />
		</inertial>
		<visual>
			<origin xyz="0 -.2 0.0" rpy="1.5707963267948 0 0" />
			<geometry>
				<cylinder length="0.4" radius="0.03"/>
			</geometry>
			<material name="mat2"/>
		</visual>
		<collision>
			<origin xyz="0 0 0.0" rpy="0 0 0" />
			<geometry>
				<cylinder length="0.4" radius="0.03"/>
			</geometry>
			<material name="mat1"/>
		</collision>
	</link>

	<link name="endarm2">
		<inertial>
			<origin xyz="0 0 0" rpy="1.5707963267948 0 0" /> 
			<mass value="0.391" />
			<inertia  ixx="0.00026475" ixy="0.0"  ixz="0.0"  iyy="0.00026475"  iyz="0.0"  izz="0.00011257" />
		</inertial>
		<visual>
			<origin xyz="0 0 0" rpy="1.5707963267948 0 0" />
			<geometry>
				<cylinder length="0.08" radius="0.024"/>
			</geometry>
			<material name="mat3"/>
		</visual>
		<collision>
			<origin xyz="0 0 0" rpy="1.5707963267948 0 0" />
			<geometry>
				<cylinder length="0.08" radius="0.024"/>
			</geometry>
			<material name="mat1"/>
		</collision>
	</link>


	<link name="motor3">
		<inertial>
			<origin xyz="0 0 -0.075" rpy="0 0 0" /> 
			<mass value="0.217" />
			<inertia  ixx="0.00289877" ixy="0.0"  ixz="0.0"  iyy="0.00289877"  iyz="0.0"  izz="0" />
		</inertial>
		<visual>
			<origin xyz="0 0 -0.075" rpy="0 0 0" />
			<geometry>
				<cylinder length="0.4" radius="0.008"/>
			</geometry>
			<material name="mat4"/>
		</visual>
		<collision>
			<origin xyz="0 0 -0.075" rpy="0 0 0" />
			<geometry>
				<cylinder length="0.4" radius="0.008"/>
			</geometry>
			<material name="mat1"/>
		</collision>
	</link>

	<link name="end_effector">
		<inertial>
			<origin xyz="0 0 0.125" rpy="0 0 0" /> 
			<mass value="1.0" />
			<inertia  ixx="0" ixy="0.0"  ixz="0.0"  iyy="0"  iyz="0.0"  izz="0" />
		</inertial>
		<visual>
			<origin xyz="0 0 0.125" rpy="0 0 0" />
			<geometry>
				<box size="0.02 .02 .02"/>
			</geometry>
			<color rgba=".8 0 0 1"/>
		</visual>
		<collision>
			<origin xyz="0 0 0.125" rpy="0 0 0" />
			<geometry>
				<box size="0.02 .02 .02"/>
			</geometry>
			<material name="mat1"/>
		</collision>
	</link>

	<link name="world"/>

<!-- Joints -->

	

	<joint name="fixed" type="fixed">
		<parent link="world"/>
		<child link="base_link" />
		<origin xyz="0.0 0 0.01" rpy="0 0 0" />
	</joint>

	<joint name="joint1" type="revolute">
    		<limit lower="-1.5707963267948" upper="1.5707963267948" effort="10" velocity="3" />
		<dynamics damping="0.0" friction="0.0"/>
    		<parent link="base_link" />
    		<child link="motor1" />
    		<origin xyz="0.0 0 1.34" rpy="0 0 0" />
    		<axis xyz="0 0 1" />
	</joint>

	<joint name="joint_motor_arm_1" type="fixed">
    		<parent link="motor1" />
    		<child link="arm1" />
    		<origin xyz="0.0 0 0.0" rpy="0 0 0" />
	</joint>

	<joint name="joint_arm_endarm_1" type="fixed">
    		<parent link="arm1" />
    		<child link="endarm1" />
    		<origin xyz="0.0 0 0.0" rpy="0 0 0" />
	</joint>

	<joint name="joint2" type="revolute">
    		<limit lower="-1.5707963267948" upper="1.5707963267948" effort="10" velocity="3" />
		<dynamics damping="0.0" friction="0.0"/>
    		<parent link="endarm1" />
    		<child link="motor2" />
    		<origin xyz="0.8 0 -0.09" rpy="0 0 1.5707963267948" />
    		<axis xyz="0 0 1" />
	</joint>

	<joint name="joint_motor_arm_2" type="fixed">
    		<parent link="motor2" />
    		<child link="arm2" />
    		<origin xyz="0.0 0 0.0" rpy="0 0 0" />
	</joint>

	<joint name="joint_arm_endarm_2" type="fixed">
    		<limit lower="-1.5707963267948" upper="1.5707963267948" effort="10" velocity="3" />
		<dynamics damping="0.0" friction="0.0"/>
    		<parent link="arm2" />
    		<child link="endarm2" />
    		<origin xyz="0.0 -0.42 0.0" rpy="1.5707963267948 0 0" />
    		<axis xyz="0 0 1" />
	</joint>

	<joint name="joint3" type="prismatic">
    		<limit lower="-.08" upper=".08" effort="10" velocity="3" />
		<dynamics damping="0.0" friction="0.0"/>
    		<parent link="endarm2" />
    		<child link="motor3" />
    		<origin xyz="0. -0.07 0.0" rpy="1.5707963267948 0 0" />
    		<axis xyz="0 0 1" />
	</joint>

	<joint name="joint4" type="revolute">
    		<limit lower="-3" upper="3" effort="10" velocity="3" />
		<dynamics damping="0.0" friction="0.0"/>
    		<parent link="motor3" />
    		<child link="end_effector" />
    		<origin xyz="0 0 0" rpy="0 0 0" />
    		<axis xyz="0 0 1" />
	</joint>

<!-- Transmission -->

	<transmission name="tran1">
		<type>transmission_interface/SimpleTransmission</type>
		<joint name="joint1">
			<hardwareInterface>EffortJointInterface</hardwareInterface>
		</joint>
		<actuator name="actuator1">
			<hardwareInterface>EffortJointInterface</hardwareInterface>
			<mechanicalReduction>1</mechanicalReduction>
		</actuator>
	</transmission>

	<transmission name="tran2">
		<type>transmission_interface/SimpleTransmission</type>
		<joint name="joint2">
			<hardwareInterface>EffortJointInterface</hardwareInterface>
		</joint>
		<actuator name="actuator2">
			<hardwareInterface>EffortJointInterface</hardwareInterface>
			<mechanicalReduction>1</mechanicalReduction>
		</actuator>
	</transmission>

	<transmission name="tran3">
		<type>transmission_interface/SimpleTransmission</type>
		<joint name="joint3">
			<hardwareInterface>EffortJointInterface</hardwareInterface>
		</joint>
		<actuator name="actuator3">
			<hardwareInterface>EffortJointInterface</hardwareInterface>
			<mechanicalReduction>1</mechanicalReduction>
		</actuator>
	</transmission>

	<transmission name="tran4">
		<type>transmission_interface/SimpleTransmission</type>
		<joint name="joint4">
			<hardwareInterface>EffortJointInterface</hardwareInterface>
		</joint>
		<actuator name="actuator4">
			<hardwareInterface>EffortJointInterface</hardwareInterface>
			<mechanicalReduction>1</mechanicalReduction>
		</actuator>
	</transmission>

</robot>
